Workbook
Name NativeTimeline_Date: #N/A
Name NativeTimeline_Timestamp: #N/A
Name Slicer_Customer_Name: #N/A
Name Slicer_Customer_Segment: #N/A
Name Slicer_Product_Name: #N/A
Name Slicer_Product_Name1: #N/A
Name Slicer_Region: #N/A
Name Slicer_Region1: #N/A
Name Slicer_Total_Amount: #N/A

Sheet Raw data 
A1: Transaction_ID | B1: Date | C1: Customer_ID | D1: Customer_Name | E1: Product_ID | F1: Product_Name | G1: Category | H1: Quantity | I1: Unit_Price | J1: Payment_Method | K1: Region | L1: Customer_Segment | M1: Customer_Since | N1: Total_Amount
A2: TRX0155 | B2: 45393 | C2: CUST023 | D2: Paul Baker | E2: P009 | F2: Monitor | G2: Electronics | H2: 3 | I2: 249.99 | J2: Cash | K2: Central | L2: Basic | M2: 44425 | N2: 749.97
A3: TRX0023 | B3: 45396 | C3: CUST013 | D3: Joseph Jackson | E3: P009 | F3: Monitor | G3: Electronics | H3: 3 | I3: 249.99 | J3: Credit Card | K3: Central | L3: Premium | M3: 44575 | N3: 749.97
A4: TRX0139 | B4: 45399 | C4: CUST021 | D4: Kevin Scott | E4: P005 | F4: Blender | G4: Appliances | H4: 3 | I4: 59.99 | J4: PayPal | K4: South | L4: Standard | M4: 45262 | N4: 179.97
A5: TRX0043 | B5: 45400 | C5: CUST046 | D5: Kathleen Bennett | E5: P005 | F5: Blender | G5: Appliances | H5: 3 | I5: 59.99 | J5: Cash | K5: North | L5: Premium | M5: 45114 | N5: 179.97
A6: TRX0212 | B6: 45400 | C6: CUST003 | D6: Michael Brown | E6: P008 | F6: Bookshelf | G6: Furniture | H6: 5 | I6: 149.99 | J6: Credit Card | K6: North | L6: Premium | M6: 45295 | N6: 749.95
A7: TRX0092 | B7: 45403 | C7: CUST024 | D7: Dorothy Nelson | E7: P005 | F7: Blender | G7: Appliances | H7: 2 | I7: 59.99 | J7: Cash | K7: West | L7: Standard | M7: 44746 | N7: 119.98
A8: TRX0193 | B8: 45403 | C8: CUST024 | D8: Dorothy Nelson | E8: P003 | F8: Headphones | G8: Electronics | H8: 5 | I8: 149.99 | J8: Credit Card | K8: Central | L8: Standard | M8: 44418 | N8: 749.95
A9: TRX0240 | B9: 45403 | C9: CUST017 | D9: Charles Allen | E9: P005 | F9: Blender | G9: Appliances | H9: 3 | I9: 59.99 | J9: Debit Card | K9: South | L9: Basic | M9: 45007 | N9: 179.97
A10: TRX0135 | B10: 45405 | C10: CUST009 | D10: Robert Thomas | E10: P001 | F10: Laptop | G10: Electronics | H10: 3 | I10: 899.99 | J10: PayPal | K10: East | L10: Standard | M10: 45299 | N10: 2699.97
A11: TRX0185 | B11: 45408 | C11: CUST026 | D11: Karen Hill | E11: P005 | F11: Blender | G11: Appliances | H11: 3 | I11: 59.99 | J11: Cash | K11: West | L11: Premium | M11: 45207 | N11: 179.97
A12: TRX0138 | B12: 45408 | C12: CUST022 | D12: Susan Green | E12: P008 | F12: Bookshelf | G12: Furniture | H12: 1 | I12: 149.99 | J12: Credit Card | K12: West | L12: Standard | M12: 45103 | N12: 149.99
A13: TRX0209 | B13: 45408 | C13: CUST046 | D13: Kathleen Bennett | E13: P008 | F13: Bookshelf | G13: Furniture | H13: 5 | I13: 149.99 | J13: Debit Card | K13: North | L13: Basic | M13: 44830 | N13: 749.95
... A251: TRX0064 | B251: 45758 | C251: CUST031 | D251: Steven Turner | E251: P010 | F251: Keyboard | G251: Electronics | H251: 3 | I251: 89.99 | J251: Debit Card | K251: North | L251: Premium | M251: 44878 | N251: 269.97

Sheet Analysis
A1: Transaction_ID | B1: Date | C1: Customer_ID | D1: Customer_Name | E1: Product_ID | F1: Product_Name | G1: Category | H1: Quantity | I1: Unit_Price | J1: Payment_Method | K1: Region | L1: Customer_Segment | M1: Customer_Since | N1: Total_Amount | O1: Month Extract | P1: Year | Q1: Customer Age | R1: Month End | S1: Timestamp | T1: Sale Amount | U1: Total Spend | V1: Most Purchased product | W1: Customer Frequency | Y1: Name | Z1: Name | AA1: common names | AC1: Customer name | AD1: Total Spend
A2: TRX0155 | B2: 45393 | C2: CUST023 | D2: Paul Baker | E2: P009 | F2: Monitor | G2: Electronics | H2: 3 | I2: 249.99 | J2: Cash | K2: Central | L2: Basic | M2: 44425 | N2: 749.97 | O2: =TEXT(B2,"mmm") -> Apr | P2: =YEAR(B2) -> 2024 | Q2: =DATEDIF(M2,TODAY(),"D") -> 1856 | R2: =EOMONTH(B2,0) -> 45412 | S2: =NOW() -> 46281.657 | T2: =IF(N2>1000,"High Sale","Low Sale") -> Low Sale | U2: =SUMIFS($N:$N, $D:$D, D2) -> 8059.75 | V2: {=INDEX(F2:F171,MODE(MATCH(F2:F171,F2:F171,0)))} -> Bookshelf | W2: =COUNTIF($D$2:$D$171,D2) -> 7 | Y2: Rahul | Z2: Amit | AA2: {=_xlfn.UNIQUE(_xlfn._xlws.FILTER(Y2:Y100,COUNTIF(Z2:Z100,Y2:Y100)>0,"No Common Name"))} -> Amit | AC2: {=_xlfn.UNIQUE(_xlfn._xlws.FILTER($D$2:$D$251,$D$2:$D$251<>""))} -> Paul Baker | AD2: {=SUMIF($D$2:$D$251,_xlfn.ANCHORARRAY(AC2),$U$2:$U$251)} -> 56418.25
A3: TRX0023 | B3: 45396 | C3: CUST013 | D3: Joseph Jackson | E3: P009 | F3: Monitor | G3: Electronics | H3: 3 | I3: 249.99 | J3: Credit Card | K3: Central | L3: Premium | M3: 44575 | N3: 749.97 | O3: =TEXT(B3,"mmm") -> Apr | P3: =YEAR(B3) -> 2024 | Q3: =DATEDIF(M3,TODAY(),"D") -> 1706 | R3: =EOMONTH(B3,0) -> 45412 | S3: =NOW() -> 46281.657 | T3: =IF(N3>1000,"High Sale","Low Sale") -> Low Sale | U3: =SUMIFS($N:$N, $D:$D, D3) -> 2299.9 | W3: =COUNTIF($D$2:$D$171,D3) -> 3 | Y3: Priya | Z3: Neha | AA3: Neha | AC3: Joseph Jackson | AD3: 6899.7
A4: TRX0139 | B4: 45399 | C4: CUST021 | D4: Kevin Scott | E4: P005 | F4: Blender | G4: Appliances | H4: 3 | I4: 59.99 | J4: PayPal | K4: South | L4: Standard | M4: 45262 | N4: 179.97 | O4: =TEXT(B4,"mmm") -> Apr | P4: =YEAR(B4) -> 2024 | Q4: =DATEDIF(M4,TODAY(),"D") -> 1019 | R4: =EOMONTH(B4,0) -> 45412 | S4: =NOW() -> 46281.657 | T4: =IF(N4>1000,"High Sale","Low Sale") -> Low Sale | U4: =SUMIFS($N:$N, $D:$D, D4) -> 3179.88 | W4: =COUNTIF($D$2:$D$171,D4) -> 5 | Y4: Amit | Z4: Rohan | AA4: Rohan | AC4: Kevin Scott | AD4: 15899.4
A5: TRX0043 | B5: 45400 | C5: CUST046 | D5: Kathleen Bennett | E5: P005 | F5: Blender | G5: Appliances | H5: 3 | I5: 59.99 | J5: Cash | K5: North | L5: Premium | M5: 45114 | N5: 179.97 | O5: =TEXT(B5,"mmm") -> Apr | P5: =YEAR(B5) -> 2024 | Q5: =DATEDIF(M5,TODAY(),"D") -> 1167 | R5: =EOMONTH(B5,0) -> 45412 | S5: =NOW() -> 46281.657 | T5: =IF(N5>1000,"High Sale","Low Sale") -> Low Sale | U5: =SUMIFS($N:$N, $D:$D, D5) -> 1229.9 | W5: =COUNTIF($D$2:$D$171,D5) -> 3 | Y5: Neha | Z5: Meena | AA5: Vikas | AC5: Kathleen Bennett | AD5: 3689.7
A6: TRX0212 | B6: 45400 | C6: CUST003 | D6: Michael Brown | E6: P008 | F6: Bookshelf | G6: Furniture | H6: 5 | I6: 149.99 | J6: Credit Card | K6: North | L6: Premium | M6: 45295 | N6: 749.95 | O6: =TEXT(B6,"mmm") -> Apr | P6: =YEAR(B6) -> 2024 | Q6: =DATEDIF(M6,TODAY(),"D") -> 986 | R6: =EOMONTH(B6,0) -> 45412 | S6: =NOW() -> 46281.657 | T6: =IF(N6>1000,"High Sale","Low Sale") -> Low Sale | U6: =SUMIFS($N:$N, $D:$D, D6) -> 3569.8 | W6: =COUNTIF($D$2:$D$171,D6) -> 7 | Y6: Rohan | Z6: Vikas | AA6: Pooja | AC6: Michael Brown | AD6: 24988.6
A7: TRX0092 | B7: 45403 | C7: CUST024 | D7: Dorothy Nelson | E7: P005 | F7: Blender | G7: Appliances | H7: 2 | I7: 59.99 | J7: Cash | K7: West | L7: Standard | M7: 44746 | N7: 119.98 | O7: =TEXT(B7,"mmm") -> Apr | P7: =YEAR(B7) -> 2024 | Q7: =DATEDIF(M7,TODAY(),"D") -> 1535 | R7: =EOMONTH(B7,0) -> 45412 | S7: =NOW() -> 46281.657 | T7: =IF(N7>1000,"High Sale","Low Sale") -> Low Sale | U7: =SUMIFS($N:$N, $D:$D, D7) -> 7369.82 | W7: =COUNTIF($D$2:$D$171,D7) -> 5 | Y7: Sneha | Z7: Pooja | AA7: Karan | AC7: Dorothy Nelson | AD7: 36849.1
A8: TRX0193 | B8: 45403 | C8: CUST024 | D8: Dorothy Nelson | E8: P003 | F8: Headphones | G8: Electronics | H8: 5 | I8: 149.99 | J8: Credit Card | K8: Central | L8: Standard | M8: 44418 | N8: 749.95 | O8: =TEXT(B8,"mmm") -> Apr | P8: =YEAR(B8) -> 2024 | Q8: =DATEDIF(M8,TODAY(),"D") -> 1863 | R8: =EOMONTH(B8,0) -> 45412 | S8: =NOW() -> 46281.657 | T8: =IF(N8>1000,"High Sale","Low Sale") -> Low Sale | U8: =SUMIFS($N:$N, $D:$D, D8) -> 7369.82 | W8: =COUNTIF($D$2:$D$171,D8) -> 5 | Y8: Vikas | Z8: Arjun | AC8: Charles Allen | AD8: 34438.25
A9: TRX0240 | B9: 45403 | C9: CUST017 | D9: Charles Allen | E9: P005 | F9: Blender | G9: Appliances | H9: 3 | I9: 59.99 | J9: Debit Card | K9: South | L9: Basic | M9: 45007 | N9: 179.97 | O9: =TEXT(B9,"mmm") -> Apr | P9: =YEAR(B9) -> 2024 | Q9: =DATEDIF(M9,TODAY(),"D") -> 1274 | R9: =EOMONTH(B9,0) -> 45412 | S9: =NOW() -> 46281.657 | T9: =IF(N9>1000,"High Sale","Low Sale") -> Low Sale | U9: =SUMIFS($N:$N, $D:$D, D9) -> 4919.75 | W9: =COUNTIF($D$2:$D$171,D9) -> 7 | Y9: Pooja | Z9: Karan | AC9: Robert Thomas | AD9: 13319.68
A10: TRX0135 | B10: 45405 | C10: CUST009 | D10: Robert Thomas | E10: P001 | F10: Laptop | G10: Electronics | H10: 3 | I10: 899.99 | J10: PayPal | K10: East | L10: Standard | M10: 45299 | N10: 2699.97 | O10: =TEXT(B10,"mmm") -> Apr | P10: =YEAR(B10) -> 2024 | Q10: =DATEDIF(M10,TODAY(),"D") -> 982 | R10: =EOMONTH(B10,0) -> 45412 | S10: =NOW() -> 46281.657 | T10: =IF(N10>1000,"High Sale","Low Sale") -> High Sale | U10: =SUMIFS($N:$N, $D:$D, D10) -> 3329.92 | W10: =COUNTIF($D$2:$D$171,D10) -> 4 | Y10: Karan | Z10: Simran | AC10: Karen Hill | AD10: 30799.25
A11: TRX0185 | B11: 45408 | C11: CUST026 | D11: Karen Hill | E11: P005 | F11: Blender | G11: Appliances | H11: 3 | I11: 59.99 | J11: Cash | K11: West | L11: Premium | M11: 45207 | N11: 179.97 | O11: =TEXT(B11,"mmm") -> Apr | P11: =YEAR(B11) -> 2024 | Q11: =DATEDIF(M11,TODAY(),"D") -> 1074 | R11: =EOMONTH(B11,0) -> 45412 | S11: =NOW() -> 46281.657 | T11: =IF(N11>1000,"High Sale","Low Sale") -> Low Sale | U11: =SUMIFS($N:$N, $D:$D, D11) -> 6159.85 | W11: =COUNTIF($D$2:$D$171,D11) -> 5 | Y11: Anjali | AC11: Susan Green | AD11: 5669.7
A12: TRX0138 | B12: 45408 | C12: CUST022 | D12: Susan Green | E12: P008 | F12: Bookshelf | G12: Furniture | H12: 1 | I12: 149.99 | J12: Credit Card | K12: West | L12: Standard | M12: 45103 | N12: 149.99 | O12: =TEXT(B12,"mmm") -> Apr | P12: =YEAR(B12) -> 2024 | Q12: =DATEDIF(M12,TODAY(),"D") -> 1178 | R12: =EOMONTH(B12,0) -> 45412 | S12: =NOW() -> 46281.657 | T12: =IF(N12>1000,"High Sale","Low Sale") -> Low Sale | U12: =SUMIFS($N:$N, $D:$D, D12) -> 1889.9 | W12: =COUNTIF($D$2:$D$171,D12) -> 3 | AC12: Peter Richardson | AD12: 8099.76
A13: TRX0209 | B13: 45408 | C13: CUST046 | D13: Kathleen Bennett | E13: P008 | F13: Bookshelf | G13: Furniture | H13: 5 | I13: 149.99 | J13: Debit Card | K13: North | L13: Basic | M13: 44830 | N13: 749.95 | O13: =TEXT(B13,"mmm") -> Apr | P13: =YEAR(B13) -> 2024 | Q13: =DATEDIF(M13,TODAY(),"D") -> 1451 | R13: =EOMONTH(B13,0) -> 45412 | S13: =NOW() -> 46281.657 | T13: =IF(N13>1000,"High Sale","Low Sale") -> Low Sale | U13: =SUMIFS($N:$N, $D:$D, D13) -> 1229.9 | W13: =COUNTIF($D$2:$D$171,D13) -> 3 | AC13: Dennis Gray | AD13: 959.84
A14: TRX0246 | B14: 45408 | C14: CUST041 | D14: Peter Richardson | E14: P008 | F14: Bookshelf | G14: Furniture | H14: 3 | I14: 149.99 | J14: Cash | K14: North | L14: Premium | M14: 44806 | N14: 449.97 | O14: =TEXT(B14,"mmm") -> Apr | P14: =YEAR(B14) -> 2024 | Q14: =DATEDIF(M14,TODAY(),"D") -> 1475 | R14: =EOMONTH(B14,0) -> 45412 | S14: =NOW() -> 46281.657 | T14: =IF(N14>1000,"High Sale","Low Sale") -> Low Sale | U14: =SUMIFS($N:$N, $D:$D, D14) -> 2699.92 | W14: =COUNTIF($D$2:$D$171,D14) -> 3 | AC14: Michelle Rogers | AD14: 8399.88
A15: TRX0067 | B15: 45409 | C15: CUST043 | D15: Dennis Gray | E15: P005 | F15: Blender | G15: Appliances | H15: 3 | I15: 59.99 | J15: Credit Card | K15: North | L15: Standard | M15: 45351 | N15: 179.97 | O15: =TEXT(B15,"mmm") -> Apr | P15: =YEAR(B15) -> 2024 | Q15: =DATEDIF(M15,TODAY(),"D") -> 930 | R15: =EOMONTH(B15,0) -> 45412 | S15: =NOW() -> 46281.657 | T15: =IF(N15>1000,"High Sale","Low Sale") -> Low Sale | U15: =SUMIFS($N:$N, $D:$D, D15) -> 479.92 | W15: =COUNTIF($D$2:$D$171,D15) -> 2 | AC15: George Adams | AD15: 2159.92
A16: TRX0191 | B16: 45409 | C16: CUST038 | D16: Michelle Rogers | E16: P002 | F16: Smartphone | G16: Electronics | H16: 3 | I16: 699.99 | J16: Credit Card | K16: West | L16: Basic | M16: 44577 | N16: 2099.97 | O16: =TEXT(B16,"mmm") -> Apr | P16: =YEAR(B16) -> 2024 | Q16: =DATEDIF(M16,TODAY(),"D") -> 1704 | R16: =EOMONTH(B16,0) -> 45412 | S16: =NOW() -> 46281.657 | T16: =IF(N16>1000,"High Sale","Low Sale") -> High Sale | U16: =SUMIFS($N:$N, $D:$D, D16) -> 4199.94 | W16: =COUNTIF($D$2:$D$171,D16) -> 2 | AC16: Mark Carter | AD16: 99198.08
A17: TRX0230 | B17: 45409 | C17: CUST027 | D17: George Adams | E17: P001 | F17: Laptop | G17: Electronics | H17: 1 | I17: 899.99 | J17: Debit Card | K17: North | L17: Standard | M17: 44920 | N17: 899.99 | O17: =TEXT(B17,"mmm") -> Apr | P17: =YEAR(B17) -> 2024 | Q17: =DATEDIF(M17,TODAY(),"D") -> 1361 | R17: =EOMONTH(B17,0) -> 45412 | S17: =NOW() -> 46281.657 | T17: =IF(N17>1000,"High Sale","Low Sale") -> Low Sale | U17: =SUMIFS($N:$N, $D:$D, D17) -> 1079.96 | W17: =COUNTIF($D$2:$D$171,D17) -> 2 | AC17: Maria Garcia | AD17: 3399.92
A18: TRX0049 | B18: 45410 | C18: CUST025 | D18: Mark Carter | E18: P008 | F18: Bookshelf | G18: Furniture | H18: 4 | I18: 149.99 | J18: Debit Card | K18: North | L18: Premium | M18: 45374 | N18: 599.96 | O18: =TEXT(B18,"mmm") -> Apr | P18: =YEAR(B18) -> 2024 | Q18: =DATEDIF(M18,TODAY(),"D") -> 907 | R18: =EOMONTH(B18,0) -> 45412 | S18: =NOW() -> 46281.657 | T18: =IF(N18>1000,"High Sale","Low Sale") -> Low Sale | U18: =SUMIFS($N:$N, $D:$D, D18) -> 12399.76 | W18: =COUNTIF($D$2:$D$171,D18) -> 8 | AC18: Virginia Sanders | AD18: 28738.74
A19: TRX0134 | B19: 45410 | C19: CUST010 | D19: Maria Garcia | E19: P002 | F19: Smartphone | G19: Electronics | H19: 2 | I19: 699.99 | J19: Cash | K19: North | L19: Basic | M19: 44781 | N19: 1399.98 | O19: =TEXT(B19,"mmm") -> Apr | P19: =YEAR(B19) -> 2024 | Q19: =DATEDIF(M19,TODAY(),"D") -> 1500 | R19: =EOMONTH(B19,0) -> 45412 | S19: =NOW() -> 46281.657 | T19: =IF(N19>1000,"High Sale","Low Sale") -> High Sale | U19: =SUMIFS($N:$N, $D:$D, D19) -> 1699.96 | W19: =COUNTIF($D$2:$D$171,D19) -> 2 | AC19: Barbara Young | AD19: 12399.84
A20: TRX0122 | B20: 45410 | C20: CUST025 | D20: Mark Carter | E20: P001 | F20: Laptop | G20: Electronics | H20: 4 | I20: 899.99 | J20: Credit Card | K20: West | L20: Standard | M20: 45327 | N20: 3599.96 | O20: =TEXT(B20,"mmm") -> Apr | P20: =YEAR(B20) -> 2024 | Q20: =DATEDIF(M20,TODAY(),"D") -> 954 | R20: =EOMONTH(B20,0) -> 45412 | S20: =NOW() -> 46281.657 | T20: =IF(N20>1000,"High Sale","Low Sale") -> High Sale | U20: =SUMIFS($N:$N, $D:$D, D20) -> 12399.76 | W20: =COUNTIF($D$2:$D$171,D20) -> 8 | AC20: Patricia Moore | AD20: 33598.74
A21: TRX0222 | B21: 45410 | C21: CUST048 | D21: Virginia Sanders | E21: P009 | F21: Monitor | G21: Electronics | H21: 3 | I21: 249.99 | J21: Credit Card | K21: North | L21: Premium | M21: 45224 | N21: 749.97 | O21: =TEXT(B21,"mmm") -> Apr | P21: =YEAR(B21) -> 2024 | Q21: =DATEDIF(M21,TODAY(),"D") -> 1057 | R21: =EOMONTH(B21,0) -> 45412 | S21: =NOW() -> 46281.657 | T21: =IF(N21>1000,"High Sale","Low Sale") -> Low Sale | U21: =SUMIFS($N:$N, $D:$D, D21) -> 4789.79 | W21: =COUNTIF($D$2:$D$171,D21) -> 6 | AC21: Cynthia Price | AD21: 8159.7
A22: TRX0231 | B22: 45412 | C22: CUST018 | D22: Barbara Young | E22: P002 | F22: Smartphone | G22: Electronics | H22: 5 | I22: 699.99 | J22: Cash | K22: West | L22: Basic | M22: 45167 | N22: 3499.95 | O22: =TEXT(B22,"mmm") -> Apr | P22: =YEAR(B22) -> 2024 | Q22: =DATEDIF(M22,TODAY(),"D") -> 1114 | R22: =EOMONTH(B22,0) -> 45412 | S22: =NOW() -> 46281.657 | T22: =IF(N22>1000,"High Sale","Low Sale") -> High Sale | U22: =SUMIFS($N:$N, $D:$D, D22) -> 6199.92 | W22: =COUNTIF($D$2:$D$171,D22) -> 2 | AC22: Nancy Collins | AD22: 18699
A23: TRX0239 | B23: 45413 | C23: CUST012 | D23: Patricia Moore | E23: P002 | F23: Smartphone | G23: Electronics | H23: 4 | I23: 699.99 | J23: Cash | K23: East | L23: Standard | M23: 44409 | N23: 2799.96 | O23: =TEXT(B23,"mmm") -> May | P23: =YEAR(B23) -> 2024 | Q23: =DATEDIF(M23,TODAY(),"D") -> 1872 | R23: =EOMONTH(B23,0) -> 45443 | S23: =NOW() -> 46281.657 | T23: =IF(N23>1000,"High Sale","Low Sale") -> High Sale | U23: =SUMIFS($N:$N, $D:$D, D23) -> 5599.79 | W23: =COUNTIF($D$2:$D$171,D23) -> 6 | AC23: Linda Martin | AD23: 2519.79
... A49: TRX0088 | B49: 45456 | C49: CUST006 | D49: Lisa Anderson | E49: P010 | F49: Keyboard | G49: Electronics | H49: 5 | I49: 89.99 | J49: Cash | K49: Central | L49: Premium | M49: 44579 | N49: 449.95 | O49: =TEXT(B49,"mmm") -> Jun | P49: =YEAR(B49) -> 2024 | Q49: =DATEDIF(M49,TODAY(),"D") -> 1702 | R49: =EOMONTH(B49,0) -> 45473 | S49: =NOW() -> 46281.657 | T49: =IF(N49>1000,"High Sale","Low Sale") -> Low Sale | U49: =SUMIFS($N:$N, $D:$D, D49) -> 2039.8 | W49: =COUNTIF($D$2:$D$171,D49) -> 5 | AC49: John Smith | AD49: 599.96
A50: TRX0115 | B50: 45459 | C50: CUST012 | D50: Patricia Moore | E50: P010 | F50: Keyboard | G50: Electronics | H50: 2 | I50: 89.99 | J50: Credit Card | K50: South | L50: Premium | M50: 44471 | N50: 179.98 | O50: =TEXT(B50,"mmm") -> Jun | P50: =YEAR(B50) -> 2024 | Q50: =DATEDIF(M50,TODAY(),"D") -> 1810 | R50: =EOMONTH(B50,0) -> 45473 | S50: =NOW() -> 46281.657 | T50: =IF(N50>1000,"High Sale","Low Sale") -> Low Sale | U50: =SUMIFS($N:$N, $D:$D, D50) -> 5599.79 | W50: =COUNTIF($D$2:$D$171,D50) -> 6
A51: TRX0154 | B51: 45459 | C51: CUST023 | D51: Paul Baker | E51: P001 | F51: Laptop | G51: Electronics | H51: 5 | I51: 899.99 | J51: Credit Card | K51: South | L51: Standard | M51: 44974 | N51: 4499.95 | O51: =TEXT(B51,"mmm") -> Jun | P51: =YEAR(B51) -> 2024 | Q51: =DATEDIF(M51,TODAY(),"D") -> 1307 | R51: =EOMONTH(B51,0) -> 45473 | S51: =NOW() -> 46281.657 | T51: =IF(N51>1000,"High Sale","Low Sale") -> High Sale | U51: =SUMIFS($N:$N, $D:$D, D51) -> 8059.75 | W51: =COUNTIF($D$2:$D$171,D51) -> 7
A52: TRX0190 | B52: 45583 | C52: CUST039 | D52: Lawrence Reed | E52: P003 | F52: Headphones | G52: Electronics | H52: 2 | I52: 149.99 | J52: Credit Card | K52: West | L52: Basic | M52: 44916 | N52: 299.98 | O52: =TEXT(B52,"mmm") -> Oct | P52: =YEAR(B52) -> 2024 | Q52: =DATEDIF(M52,TODAY(),"D") -> 1365 | R52: =EOMONTH(B52,0) -> 45596 | S52: =NOW() -> 46281.657 | T52: =IF(N52>1000,"High Sale","Low Sale") -> Low Sale | U52: =SUMIFS($N:$N, $D:$D, D52) -> 5349.82 | W52: =COUNTIF($D$2:$D$171,D52) -> 6
A53: TRX0079 | B53: 45586 | C53: CUST039 | D53: Lawrence Reed | E53: P010 | F53: Keyboard | G53: Electronics | H53: 3 | I53: 89.99 | J53: PayPal | K53: Central | L53: Basic | M53: 44551 | N53: 269.97 | O53: =TEXT(B53,"mmm") -> Oct | P53: =YEAR(B53) -> 2024 | Q53: =DATEDIF(M53,TODAY(),"D") -> 1730 | R53: =EOMONTH(B53,0) -> 45596 | S53: =NOW() -> 46281.657 | T53: =IF(N53>1000,"High Sale","Low Sale") -> Low Sale | U53: =SUMIFS($N:$N, $D:$D, D53) -> 5349.82 | W53: =COUNTIF($D$2:$D$171,D53) -> 6
A54: TRX0095 | B54: 45588 | C54: CUST046 | D54: Kathleen Bennett | E54: P003 | F54: Headphones | G54: Electronics | H54: 2 | I54: 149.99 | J54: PayPal | K54: Central | L54: Basic | M54: 44473 | N54: 299.98 | O54: =TEXT(B54,"mmm") -> Oct | P54: =YEAR(B54) -> 2024 | Q54: =DATEDIF(M54,TODAY(),"D") -> 1808 | R54: =EOMONTH(B54,0) -> 45596 | S54: =NOW() -> 46281.657 | T54: =IF(N54>1000,"High Sale","Low Sale") -> Low Sale | U54: =SUMIFS($N:$N, $D:$D, D54) -> 1229.9 | W54: =COUNTIF($D$2:$D$171,D54) -> 3
A55: TRX0009 | B55: 45588 | C55: CUST004 | D55: Sarah Davis | E55: P002 | F55: Smartphone | G55: Electronics | H55: 2 | I55: 699.99 | J55: Cash | K55: Central | L55: Basic | M55: 44992 | N55: 1399.98 | O55: =TEXT(B55,"mmm") -> Oct | P55: =YEAR(B55) -> 2024 | Q55: =DATEDIF(M55,TODAY(),"D") -> 1289 | R55: =EOMONTH(B55,0) -> 45596 | S55: =NOW() -> 46281.657 | T55: =IF(N55>1000,"High Sale","Low Sale") -> High Sale | U55: =SUMIFS($N:$N, $D:$D, D55) -> 4699.85 | W55: =COUNTIF($D$2:$D$171,D55) -> 4
A56: TRX0167 | B56: 45589 | C56: CUST028 | D56: Betty Campbell | E56: P002 | F56: Smartphone | G56: Electronics | H56: 5 | I56: 699.99 | J56: Cash | K56: North | L56: Premium | M56: 44635 | N56: 3499.95 | O56: =TEXT(B56,"mmm") -> Oct | P56: =YEAR(B56) -> 2024 | Q56: =DATEDIF(M56,TODAY(),"D") -> 1646 | R56: =EOMONTH(B56,0) -> 45596 | S56: =NOW() -> 46281.657 | T56: =IF(N56>1000,"High Sale","Low Sale") -> High Sale | U56: =SUMIFS($N:$N, $D:$D, D56) -> 4589.9 | W56: =COUNTIF($D$2:$D$171,D56) -> 3
A57: TRX0153 | B57: 45592 | C57: CUST049 | D57: Raymond Ross | E57: P010 | F57: Keyboard | G57: Electronics | H57: 3 | I57: 89.99 | J57: Credit Card | K57: North | L57: Standard | M57: 44615 | N57: 269.97 | O57: =TEXT(B57,"mmm") -> Oct | P57: =YEAR(B57) -> 2024 | Q57: =DATEDIF(M57,TODAY(),"D") -> 1666 | R57: =EOMONTH(B57,0) -> 45596 | S57: =NOW() -> 46281.657 | T57: =IF(N57>1000,"High Sale","Low Sale") -> Low Sale | U57: =SUMIFS($N:$N, $D:$D, D57) -> 269.97 | W57: =COUNTIF($D$2:$D$171,D57) -> 1
A58: TRX0057 | B58: 45597 | C58: CUST023 | D58: Paul Baker | E58: P009 | F58: Monitor | G58: Electronics | H58: 5 | I58: 249.99 | J58: Credit Card | K58: South | L58: Standard | M58: 44881 | N58: 1249.95 | O58: =TEXT(B58,"mmm") -> Nov | P58: =YEAR(B58) -> 2024 | Q58: =DATEDIF(M58,TODAY(),"D") -> 1400 | R58: =EOMONTH(B58,0) -> 45626 | S58: =NOW() -> 46281.657 | T58: =IF(N58>1000,"High Sale","Low Sale") -> High Sale | U58: =SUMIFS($N:$N, $D:$D, D58) -> 8059.75 | W58: =COUNTIF($D$2:$D$171,D58) -> 7
A59: TRX0017 | B59: 45600 | C59: CUST026 | D59: Karen Hill | E59: P007 | F59: Desk | G59: Furniture | H59: 3 | I59: 299.99 | J59: Credit Card | K59: South | L59: Standard | M59: 44502 | N59: 899.97 | O59: =TEXT(B59,"mmm") -> Nov | P59: =YEAR(B59) -> 2024 | Q59: =DATEDIF(M59,TODAY(),"D") -> 1779 | R59: =EOMONTH(B59,0) -> 45626 | S59: =NOW() -> 46281.657 | T59: =IF(N59>1000,"High Sale","Low Sale") -> Low Sale | U59: =SUMIFS($N:$N, $D:$D, D59) -> 6159.85 | W59: =COUNTIF($D$2:$D$171,D59) -> 5
A60: TRX0060 | B60: 45603 | C60: CUST012 | D60: Patricia Moore | E60: P010 | F60: Keyboard | G60: Electronics | H60: 3 | I60: 89.99 | J60: Credit Card | K60: North | L60: Premium | M60: 44420 | N60: 269.97 | O60: =TEXT(B60,"mmm") -> Nov | P60: =YEAR(B60) -> 2024 | Q60: =DATEDIF(M60,TODAY(),"D") -> 1861 | R60: =EOMONTH(B60,0) -> 45626 | S60: =NOW() -> 46281.657 | T60: =IF(N60>1000,"High Sale","Low Sale") -> Low Sale | U60: =SUMIFS($N:$N, $D:$D, D60) -> 5599.79 | W60: =COUNTIF($D$2:$D$171,D60) -> 6
A61: TRX0109 | B61: 45604 | C61: CUST010 | D61: Maria Garcia | E61: P008 | F61: Bookshelf | G61: Furniture | H61: 2 | I61: 149.99 | J61: Credit Card | K61: West | L61: Premium | M61: 44848 | N61: 299.98 | O61: =TEXT(B61,"mmm") -> Nov | P61: =YEAR(B61) -> 2024 | Q61: =DATEDIF(M61,TODAY(),"D") -> 1433 | R61: =EOMONTH(B61,0) -> 45626 | S61: =NOW() -> 46281.657 | T61: =IF(N61>1000,"High Sale","Low Sale") -> Low Sale | U61: =SUMIFS($N:$N, $D:$D, D61) -> 1699.96 | W61: =COUNTIF($D$2:$D$171,D61) -> 2
... A171: TRX0064 | B171: 45758 | C171: CUST031 | D171: Steven Turner | E171: P010 | F171: Keyboard | G171: Electronics | H171: 3 | I171: 89.99 | J171: Debit Card | K171: North | L171: Premium | M171: 44878 | N171: 269.97 | O171: =TEXT(B171,"mmm") -> Apr | P171: =YEAR(B171) -> 2025 | Q171: =DATEDIF(M171,TODAY(),"D") -> 1403 | R171: =EOMONTH(B171,0) -> 45777 | S171: =NOW() -> 46281.657 | T171: =IF(N171>1000,"High Sale","Low Sale") -> Low Sale | U171: =SUMIFS($N:$N, $D:$D, D171) -> 2469.86 | W171: =COUNTIF($D$2:$D$171,D171) -> 5

Sheet WHAT-IF Analysis
A2: Goal seek Before | F2: Goal seek After
A4: Product_Name | B4: Unit_Price | C4: QTY | D4: Total | F4: Product_Name | G4: Unit_Price | H4: QTY | I4: Total
A5: Monitor | B5: 249.99 | C5: 1 | D5: =B5*C5 -> 249.99 | F5: Monitor | G5: 249.99 | H5: 20.0008 | I5: =G5*H5 -> 5000
A6: Blender | B6: 59.99 | C6: 2 | D6: =B6*C6 -> 119.98 | F6: Blender | G6: 59.99 | H6: 20.003334 | I6: =G6*H6 -> 1200
A7: Bookshelf | B7: 149.99 | C7: 4 | D7: =B7*C7 -> 599.96 | F7: Bookshelf | G7: 149.99 | H7: 5.3336889 | I7: =G7*H7 -> 800
A8: Headphones | B8: 149.99 | C8: 3 | D8: =B8*C8 -> 449.97 | F8: Headphones | G8: 149.99 | H8: 4.0002667 | I8: =G8*H8 -> 600
A9: Laptop | B9: 899.99 | C9: 1 | D9: =B9*C9 -> 899.99 | F9: Laptop | G9: 899.99 | H9: 1.4444605 | I9: =G9*H9 -> 1300
A12: Scenario Manager Before | F12: Scenario Manager After | K12: Scenario Summary
M13: Current Values: | N13: High Value | O13: Low Value | P13: Medium
A14: Product_Name | B14: Unit_Price | C14: QTY | D14: Total | F14: Product_Name | G14: Unit_Price | H14: QTY | I14: Total | N14: Created by Priya on 22-03-2026 Modified by Priya on 22-03-2026 | O14: Created by Priya on 22-03-2026 Modified by Priya on 22-03-2026 | P14: Created by Priya on 22-03-2026 Modified by Priya on 22-03-2026
A15: Monitor | B15: 249.99 | C15: 1 | D15: =B15*C15 -> 249.99 | F15: Monitor | G15: 249.99 | H15: 3 | I15: =G15*H15 -> 749.97 | K15: Changing Cells:
A16: Blender | B16: 59.99 | C16: 2 | D16: =B16*C16 -> 119.98 | F16: Blender | G16: 59.99 | H16: 2 | I16: =G16*H16 -> 119.98 | L16: $H$15 | M16: 3 | N16: 7 | O16: 1 | P16: 3
A17: Bookshelf | B17: 149.99 | C17: 4 | D17: =B17*C17 -> 599.96 | F17: Bookshelf | G17: 149.99 | H17: 4 | I17: =G17*H17 -> 599.96 | L17: $H$16 | M17: 2 | N17: 8 | O17: 1 | P17: 2
A18: Headphones | B18: 149.99 | C18: 3 | D18: =B18*C18 -> 449.97 | F18: Headphones | G18: 149.99 | H18: 3 | I18: =G18*H18 -> 449.97 | L18: $H$17 | M18: 4 | N18: 9 | O18: 1 | P18: 4
A19: Laptop | B19: 899.99 | C19: 1 | D19: =B19*C19 -> 899.99 | F19: Laptop | G19: 899.99 | H19: 1 | I19: =G19*H19 -> 899.99 | L19: $H$18 | M19: 3 | N19: 8 | O19: 1 | P19: 3
L20: $H$19 | M20: 1 | N20: 9 | O20: 1 | P20: 1
K21: Result Cells:
L22: $L$3
K23: Notes: Current Values column represents values of changing cells at
K24: time Scenario Summary Report was created. Changing cells for each
K25: scenario are highlighted in gray.

Sheet Analysis Toolpak
C1: SUMMARY OUTPUT
F3: Regression Statistics
F4: Multiple R | G4: 0.45809869
F5: R Square | G5: 0.20985441
F6: Adjusted R Square | G6: 0.20665544
F7: Standard Error | G7: 921.40854
F8: Observations | G8: 249
C10: ANOVA
D11: df | E11: SS | F11: MS | G11: F | H11: Significance F
C12: Regression | D12: 1 | E12: 55694513 | F12: 55694513 | G12: 65.60062 | H12: 2.5391277e-14
C13: Residual | D13: 247 | E13: 2.0970144e+08 | F13: 848993.7
C14: Total | D14: 248 | E14: 2.6539596e+08
D16: Coefficients | E16: Standard Error | F16: t Stat | G16: P-value | H16: Lower 95% | I16: Upper 95% | J16: Lower 95.0% | K16: Upper 95.0%
C17: Intercept | D17: -148.18856 | E17: 143.94399 | F17: -1.0294877 | G17: 0.30425761 | H17: -431.70277 | I17: 135.32564 | J17: -431.70277 | K17: 135.32564
C18: 3 | D18: 353.7886 | E18: 43.680728 | F18: 8.0994209 | G18: 2.5391277e-14 | H18: 267.7544 | I18: 439.82281 | J18: 267.7544 | K18: 439.82281

Sheet Pivot table
A1: Sale Amount | D1: Sales by Product | G1: Sales by Region | K1: KPI CARDS
A3: Row Labels | B3: Sum of Total_Amount | D3: Row Labels | E3: Sum of Total_Amount | G3: Row Labels | H3: Sum of Total_Amount | K3: Total Sales | L3: Total Orders | M3: Average Sale
A4: Arthur Edwards | B4: 1559.94 | D4: Blender | E4: 5219.13 | G4: Central | H4: 41288.34 | K4: =SUM(Table2[Total_Amount]) -> 155764.67 | L4: 50 | M4: =AVERAGE(Analysis!N:N) -> 916.26276
A5: Barbara Young | B5: 10649.8 | D5: Bookshelf | E5: 15298.98 | G5: East | H5: 59288.39
A6: Betty Campbell | B6: 5649.84 | D6: Coffee Maker | E6: 3119.61 | G6: North | H6: 50808.31
A7: Carol Evans | B7: 1149.93 | D7: Desk | E7: 23399.22 | G7: South | H7: 36398.75
A8: Charles Allen | B8: 5089.73 | D8: Headphones | E8: 7049.53 | G8: West | H8: 41408.68
A9: Cynthia Price | B9: 3769.83 | D9: Keyboard | E9: 8009.11 | G9: Grand Total | H9: 229192.47
A10: Daniel King | B10: 7309.8 | D10: Laptop | E10: 67499.25
A11: David Martinez | B11: 1809.84 | D11: Monitor | E11: 21999.12
A12: Dennis Gray | B12: 479.92 | D12: Office Chair | E12: 10399.48 | G12: Customer Segment Analysis
A13: Dorothy Nelson | B13: 8269.79 | D13: Smartphone | E13: 67199.04
A14: Douglas Watson | B14: 4829.89 | D14: Grand Total | E14: 229192.47 | G14: Row Labels | H14: Sum of Total_Amount
A15: Edward Mitchell | B15: 11919.77 | G15: Basic | H15: 62177.81
A16: Elizabeth Hall | B16: 3649.86 | G16: Premium | H16: 84657.12
A17: Emma Wilson | B17: 1229.88 | D17: Monthly Sales Trend | G17: Standard | H17: 82357.54
A18: Frank Torres | B18: 1479.91 | G18: Grand Total | H18: 229192.47
A19: George Adams | B19: 3779.93 | D19: Row Labels | E19: Sum of Total_Amount
A20: Gerald Murphy | B20: 6379.87 | D20: 45412 | E20: 20919.33
A21: Harry Morgan | B21: 5519.89 | D21: 45443 | E21: 17039.35
A22: Helen Roberts | B22: 6459.79 | D22: 45473 | E22: 19299.45
A23: James Johnson | B23: 179.97 | D23: 45504 | E23: 18479.4
A24: Jennifer Taylor | B24: 4739.85 | D24: 45535 | E24: 15759.43
A25: John Smith | B25: 599.96 | D25: 45565 | E25: 12989.51
A26: Joseph Jackson | B26: 6949.84 | D26: 45596 | E26: 20609.52
A27: Julie Foster | B27: 239.96 | D27: 45626 | E27: 12309.44
A28: Karen Hill | B28: 8009.77 | D28: 45657 | E28: 23039.3
A29: Kathleen Bennett | B29: 4309.81 | D29: 45688 | E29: 25799.15
A30: Kevin Scott | B30: 3259.87 | D30: 45716 | E30: 16069.38
A31: Lawrence Reed | B31: 6989.77 | D31: 45747 | E31: 19899.38
A32: Linda Martin | B32: 1289.9 | D32: 45777 | E32: 6979.83
A33: Lisa Anderson | B33: 2039.8 | D33: Grand Total | E33: 229192.47
A34: Margaret Wright | B34: 2099.88
A35: Maria Garcia | B35: 1909.93
A36: Mark Carter | B36: 15659.65
A37: Michael Brown | B37: 6169.74
A38: Michelle Rogers | B38: 4199.94
A39: Nancy Collins | B39: 4189.77
A40: Patricia Moore | B40: 9799.73
A41: Paul Baker | B41: 8309.74
...

Sheet Charts 

Sheet Dashboards
B6: Total Sales | D6: Total Orders | F6: Average Sale
B7: =SUM(Table2[Total_Amount]) -> 155764.67 | D7: 50 | F7: =AVERAGE(Analysis!H:H) -> 3.1352941

Sheet Data storytelling
A1: DATA STORYTELLING
A4: 1. Sales Overview
A5: The dashboard provides an overview of total sales, total orders and average sales.
A7: 2. Regional Performance
A8: Regional sales are compared to identify the best-performing region and areas that need improvement.
A10: 3. Product Performance
A11: Product-wise analysis helps identify the most popular products and products with lower sales.
A13: 4. Customer Analysis
A14: Customer spending is analysed to identify high-value customers and repeating customers.
A16: 5. Business Recommendation
A17: The business should focus on high-performing regions, popular products and valuable customers to improve sales and customer retention.
A19: FINAL REPORT
A20: Project Title | B20: Sales Data Analysis
A21: Prepared By | B21: Simran Gohel
A22: Objective | B22: To analyze sales data and identify useful business insights.
A23: Tools Used | B23: Microsoft Excel
A24: Dataset | B24: Raw sales transaction data
A25: Key Analysis | B25: Total Sales, Average Sales, Highest Sale, Regional and Product Performance
A26: Conclusion | B26: The report summarizes sales performance and helps identify trends and high-performing segments.
A28: Metric | B28: Value
A29: Total Sales | B29: =SUM('Raw data '!H2:H251) -> 753
A30: Average Sales | B30: =COUNTA('Raw data '!A2:A251) -> 250
A31: Highest Sale | B31: =AVERAGE('Raw data '!H2:H251) -> 3.012
